File: data/xrd.ras
*RAS_DATA_START
*RAS_HEADER_START
*DISP_FMT_X "%.2f"
*DISP_FMT_Y "%.0f"
*DISP_FULLSCALE "30022.0000000000"
*DISP_LINE_COLOR "255.0000000000"
*DISP_LINE_STYLE "0.0000000000"
*DISP_LINE_WIDTH "0.2500000000"
*DISP_NOTE "Collected Data-38"
*DISP_OFFSET_Y "0.0000000000"
*DISP_PEAKSEARCH_UNIT_Y "CPS"
*DISP_RANGE_BOTTOM "0.0000000000"
*DISP_RANGE_LEFT "20.0000000000"
*DISP_RANGE_LOGCUTOFF "0.0100000000"
*DISP_RANGE_RIGHT "120.0000000000"
*DISP_RANGE_TOP "30022.0000000000"
*DISP_SCALE_MODE_Y "0.0000000000"
*DISP_TAB_NAME "Theta/2-Theta"
*DISP_TITLE_Y "Intensity"
*DISP_UNIT_Y "CPS"
*DISP_WINDOW_NAME "MSG_MACROENGINE"
*FILE_COMMENT " "
*FILE_MD5 ""
*FILE_MEMO " "
*FILE_OPERATOR "administrator"
*FILE_SAMPLE "powder"
*FILE_TYPE "RAS_RAW"
*FILE_USERGROUP "System Manager"
*FILE_VERSION "1.0000000000"
*HW_ATTACHMENT_ID "ATT1031"
*HW_ATTACHMENT_NAME "6サンプルチェンジャ|ASC-6"
*HW_COUNTER_ID-0 "CUT0021"
*HW_COUNTER_ID-1 "CUT0020"
*HW_COUNTER_ID-2 "CUT0020"
*HW_COUNTER_ID-3 "CMC0021"
*HW_COUNTER_NAME-0 "SC-70|SC-70"
*HW_COUNTER_NAME-1 "None|None"
*HW_COUNTER_NAME-2 "None|None"
*HW_COUNTER_NAME-3 "検出器モノクロメータ|Detector monochromator"
*HW_COUNTER_SELECT_NAME "SC-70|SC-70"
*HW_ECP_HV "671.0000000000"
*HW_ECP_HV_UNIT "V"
*HW_GONIOMETER_ID "GON0070"
*HW_GONIOMETER_NAME "MiniFlex 300/600|MiniFlex 300/600"
*HW_GONIOMETER_RADIUS-0 "79.0"
*HW_GONIOMETER_RADIUS-1 "91.5"
*HW_GONIOMETER_RADIUS-2 "150.0"
*HW_GONIOMETER_RADIUS-3 "0"
*HW_GONIOMETER_RADIUS-4 "103.4"
*HW_GONIOMETER_RADIUS-5 "150.0"
*HW_GONIOMETER_RADIUS-6 "46.6"
*HW_GONIOMETER_RADIUS-7 "160.0"
*HW_I_OPT_ID-0 "ISL0021"
*HW_I_OPT_ID-1 "ISO0021"
*HW_I_OPT_NAME-0 "発散スリット|Divergence slit"
*HW_I_OPT_NAME-1 "入射平行スリット|Incident parallel slit"
*HW_R_ATTENUATER_AUTOMODE "0"
*HW_R_OPT_ID-0 "RSS0021"
*HW_R_OPT_ID-1 "RSO0021"
*HW_R_OPT_ID-2 "RRS0021"
*HW_R_OPT_NAME-0 "散乱スリット|Scattering slit"
*HW_R_OPT_NAME-1 "受光平行スリット|Receiving soller slit"
*HW_R_OPT_NAME-2 "受光スリット|Receiving slit"
*HW_SAMPLE_HOLDER_ID "SMP0000"
*HW_SAMPLE_HOLDER_NAME "無し|None"
*HW_XG_CURRENT_MAX "15"
*HW_XG_CURRENT_MIN "2"
*HW_XG_CURRENT_RESOLUTION "1"
*HW_XG_CURRENT_UNIT "mA"
*HW_XG_FOCUS "1mm x 10mm"
*HW_XG_FOCUS_TYPE "Normal"
*HW_XG_ID "1060"
*HW_XG_NAME "300W/600W 封入管-B|300W/600W Sealed tube-B"
*HW_XG_TARGET_ATOMIC_NUMBER "29.0000000000"
*HW_XG_TARGET_NAME "Cu"
*HW_XG_TYPE "Hermetic"
*HW_XG_VOLTAGE_MAX "40"
*HW_XG_VOLTAGE_MIN "20"
*HW_XG_VOLTAGE_RESOLUTION "1"
*HW_XG_VOLTAGE_UNIT "kV"
*HW_XG_WATT_MAX "0.600"
*HW_XG_WATT_UNIT "kW"
*HW_XG_WAVE_LENGTH_ALPHA1 "1.540593"
*HW_XG_WAVE_LENGTH_ALPHA2 "1.544414"
*HW_XG_WAVE_LENGTH_BETA "1.392250"
*MEAS_COND_AXIS_NAME-0 "Theta/2-Theta"
*MEAS_COND_AXIS_NAME-1 "Spin"
*MEAS_COND_AXIS_NAME-2 "Change"
*MEAS_COND_AXIS_NAME-3 "Soller(inc.)"
*MEAS_COND_AXIS_NAME-4 "IHS"
*MEAS_COND_AXIS_NAME-5 "DS"
*MEAS_COND_AXIS_NAME-6 "SS"
*MEAS_COND_AXIS_NAME-7 "Soller(rec.)"
*MEAS_COND_AXIS_NAME-8 "RS"
*MEAS_COND_AXIS_NAME-9 "Filter"
*MEAS_COND_AXIS_NAME-10 "Monochromator"
*MEAS_COND_AXIS_NAME-11 "HV"
*MEAS_COND_AXIS_NAME-12 "PHA"
*MEAS_COND_AXIS_NAME_INTERNAL-0 "TwoThetaTheta"
*MEAS_COND_AXIS_NAME_INTERNAL-1 "Spin"
*MEAS_COND_AXIS_NAME_INTERNAL-2 "Change"
*MEAS_COND_AXIS_NAME_INTERNAL-3 "IncidentSollerSlit"
*MEAS_COND_AXIS_NAME_INTERNAL-4 "IncidentAxdSlit"
*MEAS_COND_AXIS_NAME_INTERNAL-5 "IncidentSlitBox"
*MEAS_COND_AXIS_NAME_INTERNAL-6 "ReceivingSlitBox1"
*MEAS_COND_AXIS_NAME_INTERNAL-7 "ReceivingSollerSlit"
*MEAS_COND_AXIS_NAME_INTERNAL-8 "ReceivingSlitBox2"
*MEAS_COND_AXIS_NAME_INTERNAL-9 "Filter"
*MEAS_COND_AXIS_NAME_INTERNAL-10 "CounterMonochromator"
*MEAS_COND_AXIS_NAME_INTERNAL-11 "HV"
*MEAS_COND_AXIS_NAME_INTERNAL-12 "PHA"
*MEAS_COND_AXIS_NAME_MAGICNO-0 "268632064.0000000000"
*MEAS_COND_AXIS_NAME_MAGICNO-1 "16842752.0000000000"
*MEAS_COND_AXIS_NAME_MAGICNO-2 "16842752.0000000000"
*MEAS_COND_AXIS_NAME_MAGICNO-3 "20971521.0000000000"
*MEAS_COND_AXIS_NAME_MAGICNO-4 "22020097.0000000000"
*MEAS_COND_AXIS_NAME_MAGICNO-5 "22020097.0000000000"
*MEAS_COND_AXIS_NAME_MAGICNO-6 "23068673.0000000000"
*MEAS_COND_AXIS_NAME_MAGICNO-7 "20971521.0000000000"
*MEAS_COND_AXIS_NAME_MAGICNO-8 "23068673.0000000000"
*MEAS_COND_AXIS_NAME_MAGICNO-9 "20971521.0000000000"
*MEAS_COND_AXIS_NAME_MAGICNO-10 "20971521.0000000000"
*MEAS_COND_AXIS_NAME_MAGICNO-11 "0.0000000000"
*MEAS_COND_AXIS_NAME_MAGICNO-12 "0.0000000000"
*MEAS_COND_AXIS_OFFSET-0 "0.0000000000"
*MEAS_COND_AXIS_OFFSET-1 "-"
*MEAS_COND_AXIS_OFFSET-2 "-"
*MEAS_COND_AXIS_OFFSET-3 "-"
*MEAS_COND_AXIS_OFFSET-4 "-"
*MEAS_COND_AXIS_OFFSET-5 "-"
*MEAS_COND_AXIS_OFFSET-6 "-"
*MEAS_COND_AXIS_OFFSET-7 "-"
*MEAS_COND_AXIS_OFFSET-8 "-"
*MEAS_COND_AXIS_OFFSET-9 "-"
*MEAS_COND_AXIS_OFFSET-10 "-"
*MEAS_COND_AXIS_OFFSET-11 "-"
*MEAS_COND_AXIS_OFFSET-12 "-"
*MEAS_COND_AXIS_POSITION-0 "120.0050000000"
*MEAS_COND_AXIS_POSITION-1 "0.0000000000"
*MEAS_COND_AXIS_POSITION-2 "3.0000000000"
*MEAS_COND_AXIS_POSITION-3 "5.0deg"
*MEAS_COND_AXIS_POSITION-4 "10.0mm"
*MEAS_COND_AXIS_POSITION-5 "1.250deg"
*MEAS_COND_AXIS_POSITION-6 "1.250deg"
*MEAS_COND_AXIS_POSITION-7 "5.0deg"
*MEAS_COND_AXIS_POSITION-8 "0.3mm"
*MEAS_COND_AXIS_POSITION-9 "None"
*MEAS_COND_AXIS_POSITION-10 "Bent"
*MEAS_COND_AXIS_POSITION-11 "671.0000000000"
*MEAS_COND_AXIS_POSITION-12 "500.0000000000"
*MEAS_COND_AXIS_UNIT-0 "deg"
*MEAS_COND_AXIS_UNIT-1 ""
*MEAS_COND_AXIS_UNIT-2 ""
*MEAS_COND_AXIS_UNIT-3 ""
*MEAS_COND_AXIS_UNIT-4 ""
*MEAS_COND_AXIS_UNIT-5 ""
*MEAS_COND_AXIS_UNIT-6 ""
*MEAS_COND_AXIS_UNIT-7 ""
*MEAS_COND_AXIS_UNIT-8 ""
*MEAS_COND_AXIS_UNIT-9 ""
*MEAS_COND_AXIS_UNIT-10 ""
*MEAS_COND_AXIS_UNIT-11 "V"
*MEAS_COND_AXIS_UNIT-12 "mV"
*MEAS_COND_COUNTER_CNTLOSS_CORR "0.0000000000"
*MEAS_COND_COUNTER_PHABASE "500.0000000000"
*MEAS_COND_COUNTER_PHAWINDOW "1000.0000000000"
*MEAS_COND_COUNTER_PHA_UNIT "mV"
*MEAS_COND_COUNTER_TAUDIFF "0.2500000000"
*MEAS_COND_COUNTER_TAUINT "0.7500000000"
*MEAS_COND_IRRADIATION_MODE "OFF"
*MEAS_COND_IRRADIATION_WIDTH ""
*MEAS_COND_OPT_ATTR " "
*MEAS_COND_OPT_NAME ""
*MEAS_COND_UNSYMMETRIC_MODE "OFF"
*MEAS_COND_XG_CURRENT "15.0000000000"
*MEAS_COND_XG_VOLTAGE "40.0000000000"
*MEAS_COND_XG_WAVE_TYPE "Ka"
*MEAS_DATA_COUNT "10001.0000000000"
*MEAS_SCAN_AXIS_X "Theta/2-Theta"
*MEAS_SCAN_AXIS_X_INTERNAL "TwoThetaTheta"
*MEAS_SCAN_END_TIME "12/07/23 18:54:13"
*MEAS_SCAN_MODE "CONTINUOUS"
*MEAS_SCAN_MONITOR "0"
*MEAS_SCAN_RESOLUTION_X "0.0025"
*MEAS_SCAN_SPEED "0.5000"
*MEAS_SCAN_SPEED_UNIT "deg/min"
*MEAS_SCAN_START "20.0000000000"
*MEAS_SCAN_START_TIME "12/07/23 15:33:53"
*MEAS_SCAN_STEP "0.0100000000"
*MEAS_SCAN_STOP "120.0000000000"
*MEAS_SCAN_UNIT_X "deg"
*MEAS_SCAN_UNIT_Y "counts"
*SLIT_SYSTEM "0"
*RAS_HEADER_END
*RAS_INT_START
20.0000 165.0000 1.0000
20.0700 161.0000 1.0000
20.1400 170.0000 1.0000
20.2100 169.0000 1.0000
20.2800 147.0000 1.0000
20.3500 144.0000 1.0000
20.4200 151.0000 1.0000
20.4900 164.0000 1.0000
20.5600 156.0000 1.0000
20.6300 146.0000 1.0000
20.7000 147.0000 1.0000
20.7700 142.0000 1.0000
20.8400 130.0000 1.0000
20.9100 140.0000 1.0000
20.9800 138.0000 1.0000
21.0500 123.0000 1.0000
21.1200 124.0000 1.0000
21.1900 120.0000 1.0000
21.2600 109.0000 1.0000
21.3300 139.0000 1.0000
21.4000 153.0000 1.0000
21.4700 127.0000 1.0000
21.5400 128.0000 1.0000
21.6100 148.0000 1.0000
21.6800 121.0000 1.0000
21.7500 136.0000 1.0000
21.8200 135.0000 1.0000
21.8900 128.0000 1.0000
21.9600 133.0000 1.0000
22.0300 153.0000 1.0000
22.1000 129.0000 1.0000
22.1700 144.0000 1.0000
22.2400 131.0000 1.0000
22.3100 144.0000 1.0000
22.3800 114.0000 1.0000
22.4500 161.0000 1.0000
22.5200 146.0000 1.0000
22.5900 134.0000 1.0000
22.6600 151.0000 1.0000
22.7300 152.0000 1.0000
22.8000 160.0000 1.0000
22.8700 157.0000 1.0000
22.9400 158.0000 1.0000
23.0100 148.0000 1.0000
23.0800 145.0000 1.0000
23.1500 156.0000 1.0000
23.2200 174.0000 1.0000
23.2900 160.0000 1.0000
23.3600 187.0000 1.0000
23.4300 163.0000 1.0000
23.5000 167.0000 1.0000
23.5700 180.0000 1.0000
23.6400 157.0000 1.0000
23.7100 190.0000 1.0000
23.7800 187.0000 1.0000
23.8500 198.0000 1.0000
23.9200 186.0000 1.0000
23.9900 170.0000 1.0000
24.0600 191.0000 1.0000
24.1300 189.0000 1.0000
24.2000 190.0000 1.0000
24.2700 209.0000 1.0000
24.3400 200.0000 1.0000
24.4100 213.0000 1.0000
24.4800 202.0000 1.0000
24.5500 221.0000 1.0000
24.6200 207.0000 1.0000
24.6900 243.0000 1.0000
24.7600 230.0000 1.0000
24.8300 220.0000 1.0000
24.9000 250.0000 1.0000
24.9700 246.0000 1.0000
25.0400 243.0000 1.0000
25.1100 282.0000 1.0000
25.1800 274.0000 1.0000
25.2500 298.0000 1.0000
25.3200 242.0000 1.0000
25.3900 285.0000 1.0000
25.4600 344.0000 1.0000
25.5300 346.0000 1.0000
25.6000 356.0000 1.0000
25.6700 404.0000 1.0000
25.7400 483.0000 1.0000
25.8100 515.0000 1.0000
25.8800 561.0000 1.0000
25.9500 738.0000 1.0000
26.0200 1000.0000 1.0000
26.0900 1418.0000 1.0000
26.1600 2065.0000 1.0000
26.2300 3337.0000 1.0000
26.3000 5985.0000 1.0000
26.3700 10938.0000 1.0000
26.4400 18493.0000 1.0000
26.5100 26235.0000 1.0000
26.5800 29950.0000 1.0000
26.6500 21623.0000 1.0000
26.7200 8829.0000 1.0000
26.7900 3307.0000 1.0000
26.8600 2019.0000 1.0000
26.9300 1406.0000 1.0000
27.0000 966.0000 1.0000
27.0700 691.0000 1.0000
27.1400 520.0000 1.0000
27.2100 456.0000 1.0000
27.2800 410.0000 1.0000
27.3500 360.0000 1.0000
27.4200 313.0000 1.0000
27.4900 263.0000 1.0000
27.5600 225.0000 1.0000
27.6300 220.0000 1.0000
27.7000 207.0000 1.0000
27.7700 217.0000 1.0000
27.8400 210.0000 1.0000
27.9100 171.0000 1.0000
27.9800 161.0000 1.0000
28.0500 161.0000 1.0000
28.1200 166.0000 1.0000
28.1900 145.0000 1.0000
28.2600 142.0000 1.0000
28.3300 125.0000 1.0000
28.4000 142.0000 1.0000
28.4700 139.0000 1.0000
28.5400 131.0000 1.0000
28.6100 133.0000 1.0000
28.6800 121.0000 1.0000
28.7500 121.0000 1.0000
28.8200 116.0000 1.0000
28.8900 118.0000 1.0000
28.9600 102.0000 1.0000
29.0300 122.0000 1.0000
29.1000 109.0000 1.0000
29.1700 107.0000 1.0000
29.2400 120.0000 1.0000
29.3100 101.0000 1.0000
29.3800 100.0000 1.0000
29.4500 111.0000 1.0000
29.5200 102.0000 1.0000
29.5900 96.0000 1.0000
29.6600 96.0000 1.0000
29.7300 102.0000 1.0000
29.8000 96.0000 1.0000
29.8700 96.0000 1.0000
29.9400 104.0000 1.0000
30.0100 91.0000 1.0000
30.0800 87.0000 1.0000
30.1500 115.0000 1.0000
30.2200 91.0000 1.0000
30.2900 97.0000 1.0000
30.3600 104.0000 1.0000
30.4300 81.0000 1.0000
30.5000 96.0000 1.0000
30.5700 98.0000 1.0000
30.6400 84.0000 1.0000
30.7100 82.0000 1.0000
30.7800 79.0000 1.0000
30.8500 93.0000 1.0000
30.9200 96.0000 1.0000
30.9900 94.0000 1.0000
31.0600 90.0000 1.0000
31.1300 94.0000 1.0000
31.2000 81.0000 1.0000
31.2700 75.0000 1.0000
31.3400 73.0000 1.0000
31.4100 81.0000 1.0000
31.4800 77.0000 1.0000
31.5500 91.0000 1.0000
31.6200 85.0000 1.0000
31.6900 80.0000 1.0000
31.7600 71.0000 1.0000
31.8300 83.0000 1.0000
31.9000 71.0000 1.0000
31.9700 77.0000 1.0000
32.0400 62.0000 1.0000
32.1100 103.0000 1.0000
32.1800 76.0000 1.0000
32.2500 108.0000 1.0000
32.3200 85.0000 1.0000
32.3900 83.0000 1.0000
32.4600 84.0000 1.0000
32.5300 71.0000 1.0000
32.6000 86.0000 1.0000
32.6700 79.0000 1.0000
32.7400 97.0000 1.0000
32.8100 81.0000 1.0000
32.8800 79.0000 1.0000
32.9500 82.0000 1.0000
33.0200 75.0000 1.0000
33.0900 84.0000 1.0000
33.1600 80.0000 1.0000
33.2300 88.0000 1.0000
33.3000 78.0000 1.0000
33.3700 83.0000 1.0000
33.4400 72.0000 1.0000
33.5100 73.0000 1.0000
33.5800 67.0000 1.0000
33.6500 73.0000 1.0000
33.7200 77.0000 1.0000
33.7900 97.0000 1.0000
33.8600 85.0000 1.0000
33.9300 107.0000 1.0000
34.0000 84.0000 1.0000
34.0700 75.0000 1.0000
34.1400 87.0000 1.0000
34.2100 81.0000 1.0000
34.2800 78.0000 1.0000
34.3500 95.0000 1.0000
34.4200 78.0000 1.0000
34.4900 93.0000 1.0000
34.5600 87.0000 1.0000
34.6300 92.0000 1.0000
34.7000 89.0000 1.0000
34.7700 74.0000 1.0000
34.8400 92.0000 1.0000
34.9100 68.0000 1.0000
34.9800 69.0000 1.0000
35.0500 78.0000 1.0000
35.1200 80.0000 1.0000
35.1900 81.0000 1.0000
35.2600 91.0000 1.0000
35.3300 79.0000 1.0000
35.4000 83.0000 1.0000
35.4700 71.0000 1.0000
35.5400 80.0000 1.0000
35.6100 91.0000 1.0000
35.6800 76.0000 1.0000
35.7500 94.0000 1.0000
35.8200 89.0000 1.0000
35.8900 89.0000 1.0000
35.9600 85.0000 1.0000
36.0300 92.0000 1.0000
36.1000 83.0000 1.0000
36.1700 89.0000 1.0000
36.2400 88.0000 1.0000
36.3100 74.0000 1.0000
36.3800 82.0000 1.0000
36.4500 69.0000 1.0000
36.5200 88.0000 1.0000
36.5900 84.0000 1.0000
36.6600 89.0000 1.0000
36.7300 85.0000 1.0000
36.8000 86.0000 1.0000
36.8700 79.0000 1.0000
36.9400 79.0000 1.0000
37.0100 78.0000 1.0000
37.0800 86.0000 1.0000
37.1500 72.0000 1.0000
37.2200 75.0000 1.0000
37.2900 96.0000 1.0000
37.3600 73.0000 1.0000
37.4300 100.0000 1.0000
37.5000 82.0000 1.0000
37.5700 76.0000 1.0000
37.6400 94.0000 1.0000
37.7100 104.0000 1.0000
37.7800 76.0000 1.0000
37.8500 86.0000 1.0000
37.9200 78.0000 1.0000
37.9900 94.0000 1.0000
38.0600 81.0000 1.0000
38.1300 81.0000 1.0000
38.2000 81.0000 1.0000
38.2700 85.0000 1.0000
38.3400 100.0000 1.0000
38.4100 93.0000 1.0000
38.4800 108.0000 1.0000
38.5500 81.0000 1.0000
38.6200 91.0000 1.0000
38.6900 95.0000 1.0000
38.7600 76.0000 1.0000
38.8300 97.0000 1.0000
38.9000 102.0000 1.0000
38.9700 98.0000 1.0000
39.0400 74.0000 1.0000
39.1100 98.0000 1.0000
39.1800 94.0000 1.0000
39.2500 90.0000 1.0000
39.3200 98.0000 1.0000
39.3900 94.0000 1.0000
39.4600 81.0000 1.0000
39.5300 97.0000 1.0000
39.6000 104.0000 1.0000
39.6700 89.0000 1.0000
39.7400 98.0000 1.0000
39.8100 98.0000 1.0000
39.8800 72.0000 1.0000
39.9500 94.0000 1.0000
40.0200 79.0000 1.0000
40.0900 95.0000 1.0000
40.1600 96.0000 1.0000
40.2300 92.0000 1.0000
40.3000 106.0000 1.0000
40.3700 90.0000 1.0000
40.4400 98.0000 1.0000
40.5100 97.0000 1.0000
40.5800 92.0000 1.0000
40.6500 97.0000 1.0000
40.7200 91.0000 1.0000
40.7900 90.0000 1.0000
40.8600 89.0000 1.0000
40.9300 99.0000 1.0000
41.0000 106.0000 1.0000
41.0700 109.0000 1.0000
41.1400 89.0000 1.0000
41.2100 96.0000 1.0000
41.2800 95.0000 1.0000
41.3500 100.0000 1.0000
41.4200 94.0000 1.0000
41.4900 96.0000 1.0000
41.5600 102.0000 1.0000
41.6300 99.0000 1.0000
41.7000 105.0000 1.0000
41.7700 99.0000 1.0000
41.8400 108.0000 1.0000
41.9100 104.0000 1.0000
41.9800 114.0000 1.0000
42.0500 125.0000 1.0000
42.1200 139.0000 1.0000
42.1900 152.0000 1.0000
42.2600 243.0000 1.0000
42.3300 345.0000 1.0000
42.4000 439.0000 1.0000
42.4700 399.0000 1.0000
42.5400 308.0000 1.0000
42.6100 242.0000 1.0000
42.6800 224.0000 1.0000
42.7500 201.0000 1.0000
42.8200 208.0000 1.0000
42.8900 210.0000 1.0000
42.9600 190.0000 1.0000
43.0300 241.0000 1.0000
43.1000 255.0000 1.0000
43.1700 261.0000 1.0000
43.2400 326.0000 1.0000
43.3100 355.0000 1.0000
43.3800 387.0000 1.0000
43.4500 397.0000 1.0000
43.5200 331.0000 1.0000
43.5900 341.0000 1.0000
43.6600 359.0000 1.0000
43.7300 341.0000 1.0000
43.8000 332.0000 1.0000
43.8700 360.0000 1.0000
43.9400 390.0000 1.0000
44.0100 400.0000 1.0000
44.0800 379.0000 1.0000
44.1500 405.0000 1.0000
44.2200 467.0000 1.0000
44.2900 497.0000 1.0000
44.3600 505.0000 1.0000
44.4300 611.0000 1.0000
44.5000 736.0000 1.0000
44.5700 681.0000 1.0000
44.6400 670.0000 1.0000
44.7100 549.0000 1.0000
44.7800 477.0000 1.0000
44.8500 429.0000 1.0000
44.9200 391.0000 1.0000
44.9900 327.0000 1.0000
45.0600 346.0000 1.0000
45.1300 304.0000 1.0000
45.2000 329.0000 1.0000
45.2700 294.0000 1.0000
45.3400 265.0000 1.0000
45.4100 263.0000 1.0000
45.4800 230.0000 1.0000
45.5500 251.0000 1.0000
45.6200 256.0000 1.0000
45.6900 234.0000 1.0000
45.7600 252.0000 1.0000
45.8300 231.0000 1.0000
45.9000 214.0000 1.0000
45.9700 240.0000 1.0000
46.0400 198.0000 1.0000
46.1100 207.0000 1.0000
46.1800 236.0000 1.0000
46.2500 229.0000 1.0000
46.3200 209.0000 1.0000
46.3900 194.0000 1.0000
46.4600 167.0000 1.0000
46.5300 158.0000 1.0000
46.6000 171.0000 1.0000
46.6700 131.0000 1.0000
46.7400 163.0000 1.0000
46.8100 134.0000 1.0000
46.8800 144.0000 1.0000
46.9500 116.0000 1.0000
47.0200 104.0000 1.0000
47.0900 119.0000 1.0000
47.1600 134.0000 1.0000
47.2300 113.0000 1.0000
47.3000 137.0000 1.0000
47.3700 114.0000 1.0000
47.4400 125.0000 1.0000
47.5100 118.0000 1.0000
47.5800 112.0000 1.0000
47.6500 100.0000 1.0000
47.7200 130.0000 1.0000
47.7900 105.0000 1.0000
47.8600 117.0000 1.0000
47.9300 94.0000 1.0000
48.0000 139.0000 1.0000
48.0700 113.0000 1.0000
48.1400 95.0000 1.0000
48.2100 125.0000 1.0000
48.2800 110.0000 1.0000
48.3500 118.0000 1.0000
48.4200 106.0000 1.0000
48.4900 115.0000 1.0000
48.5600 115.0000 1.0000
48.6300 122.0000 1.0000
48.7000 93.0000 1.0000
48.7700 121.0000 1.0000
48.8400 119.0000 1.0000
48.9100 101.0000 1.0000
48.9800 107.0000 1.0000
49.0500 116.0000 1.0000
49.1200 108.0000 1.0000
49.1900 99.0000 1.0000
49.2600 100.0000 1.0000
49.3300 117.0000 1.0000
49.4000 102.0000 1.0000
49.4700 129.0000 1.0000
49.5400 104.0000 1.0000
49.6100 99.0000 1.0000
49.6800 110.0000 1.0000
49.7500 101.0000 1.0000
49.8200 103.0000 1.0000
49.8900 111.0000 1.0000
49.9600 114.0000 1.0000
50.0300 128.0000 1.0000
50.1000 130.0000 1.0000
50.1700 125.0000 1.0000
50.2400 111.0000 1.0000
50.3100 130.0000 1.0000
50.3800 138.0000 1.0000
50.4500 137.0000 1.0000
50.5200 164.0000 1.0000
50.5900 180.0000 1.0000
50.6600 171.0000 1.0000
50.7300 184.0000 1.0000
50.8000 146.0000 1.0000
50.8700 133.0000 1.0000
50.9400 164.0000 1.0000
51.0100 152.0000 1.0000
51.0800 127.0000 1.0000
51.1500 115.0000 1.0000
51.2200 131.0000 1.0000
51.2900 119.0000 1.0000
51.3600 128.0000 1.0000
51.4300 126.0000 1.0000
51.5000 121.0000 1.0000
51.5700 128.0000 1.0000
51.6400 116.0000 1.0000
51.7100 127.0000 1.0000
51.7800 119.0000 1.0000
51.8500 133.0000 1.0000
51.9200 123.0000 1.0000
51.9900 96.0000 1.0000
52.0600 112.0000 1.0000
52.1300 130.0000 1.0000
52.2000 109.0000 1.0000
52.2700 106.0000 1.0000
52.3400 93.0000 1.0000
52.4100 110.0000 1.0000
52.4800 108.0000 1.0000
52.5500 104.0000 1.0000
52.6200 126.0000 1.0000
52.6900 108.0000 1.0000
52.7600 119.0000 1.0000
52.8300 139.0000 1.0000
52.9000 113.0000 1.0000
52.9700 125.0000 1.0000
53.0400 115.0000 1.0000
53.1100 112.0000 1.0000
53.1800 129.0000 1.0000
53.2500 106.0000 1.0000
53.3200 109.0000 1.0000
53.3900 136.0000 1.0000
53.4600 125.0000 1.0000
53.5300 140.0000 1.0000
53.6000 128.0000 1.0000
53.6700 123.0000 1.0000
53.7400 144.0000 1.0000
53.8100 156.0000 1.0000
53.8800 146.0000 1.0000
53.9500 156.0000 1.0000
54.0200 170.0000 1.0000
54.0900 188.0000 1.0000
54.1600 240.0000 1.0000
54.2300 302.0000 1.0000
54.3000 304.0000 1.0000
54.3700 474.0000 1.0000
54.4400 685.0000 1.0000
54.5100 1112.0000 1.0000
54.5800 1500.0000 1.0000
54.6500 1818.0000 1.0000
54.7200 1610.0000 1.0000
54.7900 1196.0000 1.0000
54.8600 888.0000 1.0000
54.9300 492.0000 1.0000
55.0000 349.0000 1.0000
55.0700 249.0000 1.0000
55.1400 241.0000 1.0000
55.2100 215.0000 1.0000
55.2800 185.0000 1.0000
55.3500 167.0000 1.0000
55.4200 163.0000 1.0000
55.4900 151.0000 1.0000
55.5600 139.0000 1.0000
55.6300 142.0000 1.0000
55.7000 125.0000 1.0000
55.7700 136.0000 1.0000
55.8400 130.0000 1.0000
55.9100 135.0000 1.0000
55.9800 120.0000 1.0000
56.0500 131.0000 1.0000
56.1200 155.0000 1.0000
56.1900 108.0000 1.0000
56.2600 162.0000 1.0000
56.3300 145.0000 1.0000
56.4000 146.0000 1.0000
56.4700 140.0000 1.0000
56.5400 139.0000 1.0000
56.6100 131.0000 1.0000
56.6800 155.0000 1.0000
56.7500 134.0000 1.0000
56.8200 127.0000 1.0000
56.8900 132.0000 1.0000
56.9600 115.0000 1.0000
57.0300 126.0000 1.0000
57.1000 134.0000 1.0000
57.1700 134.0000 1.0000
57.2400 120.0000 1.0000
57.3100 122.0000 1.0000
57.3800 138.0000 1.0000
57.4500 144.0000 1.0000
57.5200 122.0000 1.0000
57.5900 131.0000 1.0000
57.6600 122.0000 1.0000
57.7300 127.0000 1.0000
57.8000 105.0000 1.0000
57.8700 132.0000 1.0000
57.9400 118.0000 1.0000
58.0100 122.0000 1.0000
58.0800 124.0000 1.0000
58.1500 117.0000 1.0000
58.2200 111.0000 1.0000
58.2900 110.0000 1.0000
58.3600 133.0000 1.0000
58.4300 118.0000 1.0000
58.5000 132.0000 1.0000
58.5700 125.0000 1.0000
58.6400 118.0000 1.0000
58.7100 124.0000 1.0000
58.7800 140.0000 1.0000
58.8500 146.0000 1.0000
58.9200 146.0000 1.0000
58.9900 136.0000 1.0000
59.0600 145.0000 1.0000
59.1300 129.0000 1.0000
59.2000 148.0000 1.0000
59.2700 148.0000 1.0000
59.3400 156.0000 1.0000
59.4100 138.0000 1.0000
59.4800 142.0000 1.0000
59.5500 149.0000 1.0000
59.6200 186.0000 1.0000
59.6900 181.0000 1.0000
59.7600 178.0000 1.0000
59.8300 192.0000 1.0000
59.9000 200.0000 1.0000
59.9700 177.0000 1.0000
60.0400 188.0000 1.0000
60.1100 185.0000 1.0000
60.1800 159.0000 1.0000
60.2500 161.0000 1.0000
60.3200 155.0000 1.0000
60.3900 160.0000 1.0000
60.4600 129.0000 1.0000
60.5300 116.0000 1.0000
60.6000 145.0000 1.0000
60.6700 111.0000 1.0000
60.7400 130.0000 1.0000
60.8100 109.0000 1.0000
60.8800 122.0000 1.0000
60.9500 95.0000 1.0000
61.0200 108.0000 1.0000
61.0900 112.0000 1.0000
61.1600 109.0000 1.0000
61.2300 129.0000 1.0000
61.3000 103.0000 1.0000
61.3700 118.0000 1.0000
61.4400 123.0000 1.0000
61.5100 112.0000 1.0000
61.5800 99.0000 1.0000
61.6500 92.0000 1.0000
61.7200 94.0000 1.0000
61.7900 90.0000 1.0000
61.8600 110.0000 1.0000
61.9300 99.0000 1.0000
62.0000 96.0000 1.0000
62.0700 115.0000 1.0000
62.1400 91.0000 1.0000
62.2100 93.0000 1.0000
62.2800 84.0000 1.0000
62.3500 84.0000 1.0000
62.4200 104.0000 1.0000
62.4900 117.0000 1.0000
62.5600 99.0000 1.0000
62.6300 86.0000 1.0000
62.7000 100.0000 1.0000
62.7700 109.0000 1.0000
62.8400 69.0000 1.0000
62.9100 95.0000 1.0000
62.9800 83.0000 1.0000
63.0500 94.0000 1.0000
63.1200 87.0000 1.0000
63.1900 119.0000 1.0000
63.2600 85.0000 1.0000
63.3300 89.0000 1.0000
63.4000 87.0000 1.0000
63.4700 81.0000 1.0000
63.5400 89.0000 1.0000
63.6100 81.0000 1.0000
63.6800 97.0000 1.0000
63.7500 103.0000 1.0000
63.8200 100.0000 1.0000
63.8900 89.0000 1.0000
63.9600 72.0000 1.0000
64.0300 94.0000 1.0000
64.1000 91.0000 1.0000
64.1700 94.0000 1.0000
64.2400 83.0000 1.0000
64.3100 82.0000 1.0000
64.3800 96.0000 1.0000
64.4500 89.0000 1.0000
64.5200 95.0000 1.0000
64.5900 94.0000 1.0000
64.6600 66.0000 1.0000
64.7300 92.0000 1.0000
64.8000 79.0000 1.0000
64.8700 76.0000 1.0000
64.9400 84.0000 1.0000
65.0100 72.0000 1.0000
65.0800 87.0000 1.0000
65.1500 72.0000 1.0000
65.2200 78.0000 1.0000
65.2900 70.0000 1.0000
65.3600 66.0000 1.0000
65.4300 80.0000 1.0000
65.5000 65.0000 1.0000
65.5700 71.0000 1.0000
65.6400 80.0000 1.0000
65.7100 79.0000 1.0000
65.7800 62.0000 1.0000
65.8500 76.0000 1.0000
65.9200 75.0000 1.0000
65.9900 84.0000 1.0000
66.0600 73.0000 1.0000
66.1300 72.0000 1.0000
66.2000 89.0000 1.0000
66.2700 75.0000 1.0000
66.3400 76.0000 1.0000
66.4100 68.0000 1.0000
66.4800 75.0000 1.0000
66.5500 83.0000 1.0000
66.6200 82.0000 1.0000
66.6900 81.0000 1.0000
66.7600 75.0000 1.0000
66.8300 80.0000 1.0000
66.9000 83.0000 1.0000
66.9700 88.0000 1.0000
67.0400 73.0000 1.0000
67.1100 76.0000 1.0000
67.1800 65.0000 1.0000
67.2500 86.0000 1.0000
67.3200 83.0000 1.0000
67.3900 73.0000 1.0000
67.4600 76.0000 1.0000
67.5300 66.0000 1.0000
67.6000 56.0000 1.0000
67.6700 69.0000 1.0000
67.7400 93.0000 1.0000
67.8100 78.0000 1.0000
67.8800 73.0000 1.0000
67.9500 64.0000 1.0000
68.0200 75.0000 1.0000
68.0900 74.0000 1.0000
68.1600 69.0000 1.0000
68.2300 63.0000 1.0000
68.3000 80.0000 1.0000
68.3700 76.0000 1.0000
68.4400 80.0000 1.0000
68.5100 75.0000 1.0000
68.5800 73.0000 1.0000
68.6500 74.0000 1.0000
68.7200 91.0000 1.0000
68.7900 81.0000 1.0000
68.8600 98.0000 1.0000
68.9300 85.0000 1.0000
69.0000 70.0000 1.0000
69.0700 76.0000 1.0000
69.1400 72.0000 1.0000
69.2100 81.0000 1.0000
69.2800 69.0000 1.0000
69.3500 60.0000 1.0000
69.4200 82.0000 1.0000
69.4900 74.0000 1.0000
69.5600 86.0000 1.0000
69.6300 79.0000 1.0000
69.7000 64.0000 1.0000
69.7700 56.0000 1.0000
69.8400 71.0000 1.0000
69.9100 72.0000 1.0000
69.9800 65.0000 1.0000
70.0500 83.0000 1.0000
70.1200 64.0000 1.0000
70.1900 70.0000 1.0000
70.2600 74.0000 1.0000
70.3300 81.0000 1.0000
70.4000 67.0000 1.0000
70.4700 63.0000 1.0000
70.5400 77.0000 1.0000
70.6100 93.0000 1.0000
70.6800 75.0000 1.0000
70.7500 93.0000 1.0000
70.8200 62.0000 1.0000
70.8900 76.0000 1.0000
70.9600 84.0000 1.0000
71.0300 84.0000 1.0000
71.1000 87.0000 1.0000
71.1700 95.0000 1.0000
71.2400 76.0000 1.0000
71.3100 84.0000 1.0000
71.3800 70.0000 1.0000
71.4500 74.0000 1.0000
71.5200 66.0000 1.0000
71.5900 95.0000 1.0000
71.6600 68.0000 1.0000
71.7300 65.0000 1.0000
71.8000 91.0000 1.0000
71.8700 83.0000 1.0000
71.9400 65.0000 1.0000
72.0100 89.0000 1.0000
72.0800 81.0000 1.0000
72.1500 70.0000 1.0000
72.2200 72.0000 1.0000
72.2900 84.0000 1.0000
72.3600 84.0000 1.0000
72.4300 83.0000 1.0000
72.5000 80.0000 1.0000
72.5700 72.0000 1.0000
72.6400 67.0000 1.0000
72.7100 65.0000 1.0000
72.7800 69.0000 1.0000
72.8500 78.0000 1.0000
72.9200 73.0000 1.0000
72.9900 77.0000 1.0000
73.0600 83.0000 1.0000
73.1300 66.0000 1.0000
73.2000 73.0000 1.0000
73.2700 72.0000 1.0000
73.3400 64.0000 1.0000
73.4100 86.0000 1.0000
73.4800 73.0000 1.0000
73.5500 70.0000 1.0000
73.6200 57.0000 1.0000
73.6900 77.0000 1.0000
73.7600 62.0000 1.0000
73.8300 66.0000 1.0000
73.9000 74.0000 1.0000
73.9700 76.0000 1.0000
74.0400 63.0000 1.0000
74.1100 73.0000 1.0000
74.1800 64.0000 1.0000
74.2500 73.0000 1.0000
74.3200 79.0000 1.0000
74.3900 61.0000 1.0000
74.4600 74.0000 1.0000
74.5300 58.0000 1.0000
74.6000 69.0000 1.0000
74.6700 62.0000 1.0000
74.7400 80.0000 1.0000
74.8100 69.0000 1.0000
74.8800 62.0000 1.0000
74.9500 68.0000 1.0000
75.0200 76.0000 1.0000
75.0900 68.0000 1.0000
75.1600 86.0000 1.0000
75.2300 66.0000 1.0000
75.3000 63.0000 1.0000
75.3700 75.0000 1.0000
75.4400 60.0000 1.0000
75.5100 69.0000 1.0000
75.5800 71.0000 1.0000
75.6500 72.0000 1.0000
75.7200 59.0000 1.0000
75.7900 74.0000 1.0000
75.8600 66.0000 1.0000
75.9300 78.0000 1.0000
76.0000 62.0000 1.0000
76.0700 63.0000 1.0000
76.1400 74.0000 1.0000
76.2100 79.0000 1.0000
76.2800 84.0000 1.0000
76.3500 77.0000 1.0000
76.4200 72.0000 1.0000
76.4900 62.0000 1.0000
76.5600 62.0000 1.0000
76.6300 73.0000 1.0000
76.7000 74.0000 1.0000
76.7700 61.0000 1.0000
76.8400 83.0000 1.0000
76.9100 67.0000 1.0000
76.9800 73.0000 1.0000
77.0500 77.0000 1.0000
77.1200 88.0000 1.0000
77.1900 100.0000 1.0000
77.2600 136.0000 1.0000
77.3300 272.0000 1.0000
77.4000 458.0000 1.0000
77.4700 579.0000 1.0000
77.5400 449.0000 1.0000
77.6100 375.0000 1.0000
77.6800 331.0000 1.0000
77.7500 304.0000 1.0000
77.8200 186.0000 1.0000
77.8900 114.0000 1.0000
77.9600 102.0000 1.0000
78.0300 80.0000 1.0000
78.1000 98.0000 1.0000
78.1700 77.0000 1.0000
78.2400 93.0000 1.0000
78.3100 68.0000 1.0000
78.3800 72.0000 1.0000
78.4500 68.0000 1.0000
78.5200 73.0000 1.0000
78.5900 77.0000 1.0000
78.6600 80.0000 1.0000
78.7300 79.0000 1.0000
78.8000 83.0000 1.0000
78.8700 72.0000 1.0000
78.9400 85.0000 1.0000
79.0100 55.0000 1.0000
79.0800 66.0000 1.0000
79.1500 89.0000 1.0000
79.2200 81.0000 1.0000
79.2900 82.0000 1.0000
79.3600 66.0000 1.0000
79.4300 83.0000 1.0000
79.5000 75.0000 1.0000
79.5700 77.0000 1.0000
79.6400 83.0000 1.0000
79.7100 80.0000 1.0000
79.7800 79.0000 1.0000
79.8500 81.0000 1.0000
79.9200 64.0000 1.0000
79.9900 80.0000 1.0000
80.0600 95.0000 1.0000
80.1300 78.0000 1.0000
80.2000 79.0000 1.0000
80.2700 75.0000 1.0000
80.3400 68.0000 1.0000
80.4100 80.0000 1.0000
80.4800 73.0000 1.0000
80.5500 95.0000 1.0000
80.6200 75.0000 1.0000
80.6900 80.0000 1.0000
80.7600 68.0000 1.0000
80.8300 78.0000 1.0000
80.9000 67.0000 1.0000
80.9700 72.0000 1.0000
81.0400 88.0000 1.0000
81.1100 83.0000 1.0000
81.1800 71.0000 1.0000
81.2500 105.0000 1.0000
81.3200 77.0000 1.0000
81.3900 61.0000 1.0000
81.4600 89.0000 1.0000
81.5300 72.0000 1.0000
81.6000 64.0000 1.0000
81.6700 73.0000 1.0000
81.7400 80.0000 1.0000
81.8100 78.0000 1.0000
81.8800 87.0000 1.0000
81.9500 72.0000 1.0000
82.0200 71.0000 1.0000
82.0900 77.0000 1.0000
82.1600 79.0000 1.0000
82.2300 73.0000 1.0000
82.3000 71.0000 1.0000
82.3700 96.0000 1.0000
82.4400 94.0000 1.0000
82.5100 92.0000 1.0000
82.5800 88.0000 1.0000
82.6500 89.0000 1.0000
82.7200 80.0000 1.0000
82.7900 113.0000 1.0000
82.8600 100.0000 1.0000
82.9300 103.0000 1.0000
83.0000 128.0000 1.0000
83.0700 112.0000 1.0000
83.1400 170.0000 1.0000
83.2100 153.0000 1.0000
83.2800 181.0000 1.0000
83.3500 256.0000 1.0000
83.4200 295.0000 1.0000
83.4900 434.0000 1.0000
83.5600 474.0000 1.0000
83.6300 499.0000 1.0000
83.7000 443.0000 1.0000
83.7700 417.0000 1.0000
83.8400 381.0000 1.0000
83.9100 277.0000 1.0000
83.9800 243.0000 1.0000
84.0500 190.0000 1.0000
84.1200 172.0000 1.0000
84.1900 145.0000 1.0000
84.2600 127.0000 1.0000
84.3300 118.0000 1.0000
84.4000 127.0000 1.0000
84.4700 104.0000 1.0000
84.5400 89.0000 1.0000
84.6100 104.0000 1.0000
84.6800 95.0000 1.0000
84.7500 105.0000 1.0000
84.8200 95.0000 1.0000
84.8900 105.0000 1.0000
84.9600 101.0000 1.0000
85.0300 87.0000 1.0000
85.1000 86.0000 1.0000
85.1700 110.0000 1.0000
85.2400 87.0000 1.0000
85.3100 83.0000 1.0000
85.3800 91.0000 1.0000
85.4500 82.0000 1.0000
85.5200 90.0000 1.0000
85.5900 101.0000 1.0000
85.6600 95.0000 1.0000
85.7300 78.0000 1.0000
85.8000 97.0000 1.0000
85.8700 90.0000 1.0000
85.9400 93.0000 1.0000
86.0100 73.0000 1.0000
86.0800 106.0000 1.0000
86.1500 74.0000 1.0000
86.2200 84.0000 1.0000
86.2900 89.0000 1.0000
86.3600 93.0000 1.0000
86.4300 95.0000 1.0000
86.5000 83.0000 1.0000
86.5700 95.0000 1.0000
86.6400 98.0000 1.0000
86.7100 115.0000 1.0000
86.7800 126.0000 1.0000
86.8500 154.0000 1.0000
86.9200 232.0000 1.0000
86.9900 257.0000 1.0000
87.0600 204.0000 1.0000
87.1300 243.0000 1.0000
87.2000 186.0000 1.0000
87.2700 189.0000 1.0000
87.3400 185.0000 1.0000
87.4100 154.0000 1.0000
87.4800 99.0000 1.0000
87.5500 80.0000 1.0000
87.6200 104.0000 1.0000
87.6900 85.0000 1.0000
87.7600 88.0000 1.0000
87.8300 83.0000 1.0000
87.9000 79.0000 1.0000
87.9700 76.0000 1.0000
88.0400 73.0000 1.0000
88.1100 64.0000 1.0000
88.1800 75.0000 1.0000
88.2500 69.0000 1.0000
88.3200 72.0000 1.0000
88.3900 74.0000 1.0000
88.4600 74.0000 1.0000
88.5300 77.0000 1.0000
88.6000 55.0000 1.0000
88.6700 58.0000 1.0000
88.7400 74.0000 1.0000
88.8100 76.0000 1.0000
88.8800 68.0000 1.0000
88.9500 71.0000 1.0000
89.0200 62.0000 1.0000
89.0900 82.0000 1.0000
89.1600 64.0000 1.0000
89.2300 72.0000 1.0000
89.3000 74.0000 1.0000
89.3700 81.0000 1.0000
89.4400 60.0000 1.0000
89.5100 72.0000 1.0000
89.5800 60.0000 1.0000
89.6500 72.0000 1.0000
89.7200 55.0000 1.0000
89.7900 77.0000 1.0000
89.8600 75.0000 1.0000
89.9300 74.0000 1.0000
90.0000 66.0000 1.0000
90.0700 56.0000 1.0000
90.1400 61.0000 1.0000
90.2100 53.0000 1.0000
90.2800 77.0000 1.0000
90.3500 74.0000 1.0000
90.4200 67.0000 1.0000
90.4900 66.0000 1.0000
90.5600 54.0000 1.0000
90.6300 67.0000 1.0000
90.7000 56.0000 1.0000
90.7700 49.0000 1.0000
90.8400 73.0000 1.0000
90.9100 70.0000 1.0000
90.9800 53.0000 1.0000
91.0500 60.0000 1.0000
91.1200 71.0000 1.0000
91.1900 79.0000 1.0000
91.2600 78.0000 1.0000
91.3300 56.0000 1.0000
91.4000 71.0000 1.0000
91.4700 61.0000 1.0000
91.5400 61.0000 1.0000
91.6100 62.0000 1.0000
91.6800 76.0000 1.0000
91.7500 65.0000 1.0000
91.8200 61.0000 1.0000
91.8900 68.0000 1.0000
91.9600 66.0000 1.0000
92.0300 61.0000 1.0000
92.1000 54.0000 1.0000
92.1700 55.0000 1.0000
92.2400 46.0000 1.0000
92.3100 54.0000 1.0000
92.3800 81.0000 1.0000
92.4500 60.0000 1.0000
92.5200 66.0000 1.0000
92.5900 67.0000 1.0000
92.6600 76.0000 1.0000
92.7300 69.0000 1.0000
92.8000 86.0000 1.0000
92.8700 66.0000 1.0000
92.9400 58.0000 1.0000
93.0100 75.0000 1.0000
93.0800 59.0000 1.0000
93.1500 81.0000 1.0000
93.2200 76.0000 1.0000
93.2900 76.0000 1.0000
93.3600 78.0000 1.0000
93.4300 82.0000 1.0000
93.5000 68.0000 1.0000
93.5700 60.0000 1.0000
93.6400 65.0000 1.0000
93.7100 73.0000 1.0000
93.7800 68.0000 1.0000
93.8500 74.0000 1.0000
93.9200 97.0000 1.0000
93.9900 86.0000 1.0000
94.0600 86.0000 1.0000
94.1300 97.0000 1.0000
94.2000 85.0000 1.0000
94.2700 86.0000 1.0000
94.3400 71.0000 1.0000
94.4100 62.0000 1.0000
94.4800 67.0000 1.0000
94.5500 66.0000 1.0000
94.6200 62.0000 1.0000
94.6900 66.0000 1.0000
94.7600 81.0000 1.0000
94.8300 58.0000 1.0000
94.9000 73.0000 1.0000
94.9700 57.0000 1.0000
95.0400 72.0000 1.0000
95.1100 70.0000 1.0000
95.1800 58.0000 1.0000
95.2500 61.0000 1.0000
95.3200 79.0000 1.0000
95.3900 62.0000 1.0000
95.4600 65.0000 1.0000
95.5300 65.0000 1.0000
95.6000 60.0000 1.0000
95.6700 76.0000 1.0000
95.7400 61.0000 1.0000
95.8100 51.0000 1.0000
95.8800 64.0000 1.0000
95.9500 54.0000 1.0000
96.0200 62.0000 1.0000
96.0900 62.0000 1.0000
96.1600 67.0000 1.0000
96.2300 52.0000 1.0000
96.3000 62.0000 1.0000
96.3700 68.0000 1.0000
96.4400 66.0000 1.0000
96.5100 59.0000 1.0000
96.5800 57.0000 1.0000
96.6500 62.0000 1.0000
96.7200 76.0000 1.0000
96.7900 66.0000 1.0000
96.8600 62.0000 1.0000
96.9300 53.0000 1.0000
97.0000 58.0000 1.0000
97.0700 58.0000 1.0000
97.1400 67.0000 1.0000
97.2100 53.0000 1.0000
97.2800 52.0000 1.0000
97.3500 70.0000 1.0000
97.4200 60.0000 1.0000
97.4900 56.0000 1.0000
97.5600 50.0000 1.0000
97.6300 60.0000 1.0000
97.7000 60.0000 1.0000
97.7700 67.0000 1.0000
97.8400 56.0000 1.0000
97.9100 51.0000 1.0000
97.9800 67.0000 1.0000
98.0500 53.0000 1.0000
98.1200 63.0000 1.0000
98.1900 63.0000 1.0000
98.2600 51.0000 1.0000
98.3300 74.0000 1.0000
98.4000 79.0000 1.0000
98.4700 53.0000 1.0000
98.5400 56.0000 1.0000
98.6100 60.0000 1.0000
98.6800 80.0000 1.0000
98.7500 62.0000 1.0000
98.8200 65.0000 1.0000
98.8900 67.0000 1.0000
98.9600 75.0000 1.0000
99.0300 68.0000 1.0000
99.1000 71.0000 1.0000
99.1700 56.0000 1.0000
99.2400 67.0000 1.0000
99.3100 71.0000 1.0000
99.3800 69.0000 1.0000
99.4500 64.0000 1.0000
99.5200 59.0000 1.0000
99.5900 76.0000 1.0000
99.6600 87.0000 1.0000
99.7300 76.0000 1.0000
99.8000 70.0000 1.0000
99.8700 76.0000 1.0000
99.9400 56.0000 1.0000
100.0100 61.0000 1.0000
100.0800 59.0000 1.0000
100.1500 73.0000 1.0000
100.2200 65.0000 1.0000
100.2900 78.0000 1.0000
100.3600 66.0000 1.0000
100.4300 83.0000 1.0000
100.5000 72.0000 1.0000
100.5700 84.0000 1.0000
100.6400 92.0000 1.0000
100.7100 101.0000 1.0000
100.7800 87.0000 1.0000
100.8500 73.0000 1.0000
100.9200 79.0000 1.0000
100.9900 92.0000 1.0000
101.0600 88.0000 1.0000
101.1300 103.0000 1.0000
101.2000 107.0000 1.0000
101.2700 122.0000 1.0000
101.3400 134.0000 1.0000
101.4100 167.0000 1.0000
101.4800 183.0000 1.0000
101.5500 178.0000 1.0000
101.6200 198.0000 1.0000
101.6900 236.0000 1.0000
101.7600 226.0000 1.0000
101.8300 228.0000 1.0000
101.9000 263.0000 1.0000
101.9700 231.0000 1.0000
102.0400 231.0000 1.0000
102.1100 222.0000 1.0000
102.1800 182.0000 1.0000
102.2500 202.0000 1.0000
102.3200 174.0000 1.0000
102.3900 141.0000 1.0000
102.4600 137.0000 1.0000
102.5300 127.0000 1.0000
102.6000 100.0000 1.0000
102.6700 93.0000 1.0000
102.7400 103.0000 1.0000
102.8100 95.0000 1.0000
102.8800 91.0000 1.0000
102.9500 66.0000 1.0000
103.0200 98.0000 1.0000
103.0900 87.0000 1.0000
103.1600 80.0000 1.0000
103.2300 84.0000 1.0000
103.3000 77.0000 1.0000
103.3700 64.0000 1.0000
103.4400 85.0000 1.0000
103.5100 70.0000 1.0000
103.5800 76.0000 1.0000
103.6500 67.0000 1.0000
103.7200 75.0000 1.0000
103.7900 78.0000 1.0000
103.8600 64.0000 1.0000
103.9300 74.0000 1.0000
104.0000 82.0000 1.0000
104.0700 74.0000 1.0000
104.1400 75.0000 1.0000
104.2100 66.0000 1.0000
104.2800 78.0000 1.0000
104.3500 77.0000 1.0000
104.4200 71.0000 1.0000
104.4900 75.0000 1.0000
104.5600 54.0000 1.0000
104.6300 86.0000 1.0000
104.7000 61.0000 1.0000
104.7700 70.0000 1.0000
104.8400 58.0000 1.0000
104.9100 72.0000 1.0000
104.9800 78.0000 1.0000
105.0500 56.0000 1.0000
105.1200 83.0000 1.0000
105.1900 58.0000 1.0000
105.2600 90.0000 1.0000
105.3300 80.0000 1.0000
105.4000 60.0000 1.0000
105.4700 66.0000 1.0000
105.5400 71.0000 1.0000
105.6100 71.0000 1.0000
105.6800 74.0000 1.0000
105.7500 83.0000 1.0000
105.8200 63.0000 1.0000
105.8900 70.0000 1.0000
105.9600 64.0000 1.0000
106.0300 70.0000 1.0000
106.1000 61.0000 1.0000
106.1700 57.0000 1.0000
106.2400 60.0000 1.0000
106.3100 81.0000 1.0000
106.3800 72.0000 1.0000
106.4500 66.0000 1.0000
106.5200 76.0000 1.0000
106.5900 77.0000 1.0000
106.6600 70.0000 1.0000
106.7300 73.0000 1.0000
106.8000 70.0000 1.0000
106.8700 74.0000 1.0000
106.9400 65.0000 1.0000
107.0100 60.0000 1.0000
107.0800 70.0000 1.0000
107.1500 61.0000 1.0000
107.2200 66.0000 1.0000
107.2900 84.0000 1.0000
107.3600 66.0000 1.0000
107.4300 77.0000 1.0000
107.5000 69.0000 1.0000
107.5700 63.0000 1.0000
107.6400 67.0000 1.0000
107.7100 79.0000 1.0000
107.7800 78.0000 1.0000
107.8500 59.0000 1.0000
107.9200 59.0000 1.0000
107.9900 78.0000 1.0000
108.0600 70.0000 1.0000
108.1300 59.0000 1.0000
108.2000 62.0000 1.0000
108.2700 76.0000 1.0000
108.3400 55.0000 1.0000
108.4100 54.0000 1.0000
108.4800 64.0000 1.0000
108.5500 59.0000 1.0000
108.6200 66.0000 1.0000
108.6900 67.0000 1.0000
108.7600 62.0000 1.0000
108.8300 64.0000 1.0000
108.9000 61.0000 1.0000
108.9700 68.0000 1.0000
109.0400 73.0000 1.0000
109.1100 69.0000 1.0000
109.1800 56.0000 1.0000
109.2500 62.0000 1.0000
109.3200 72.0000 1.0000
109.3900 60.0000 1.0000
109.4600 74.0000 1.0000
109.5300 62.0000 1.0000
109.6000 52.0000 1.0000
109.6700 64.0000 1.0000
109.7400 57.0000 1.0000
109.8100 65.0000 1.0000
109.8800 61.0000 1.0000
109.9500 68.0000 1.0000
110.0200 61.0000 1.0000
110.0900 62.0000 1.0000
110.1600 81.0000 1.0000
110.2300 53.0000 1.0000
110.3000 69.0000 1.0000
110.3700 68.0000 1.0000
110.4400 56.0000 1.0000
110.5100 59.0000 1.0000
110.5800 70.0000 1.0000
110.6500 72.0000 1.0000
110.7200 55.0000 1.0000
110.7900 64.0000 1.0000
110.8600 64.0000 1.0000
110.9300 57.0000 1.0000
111.0000 70.0000 1.0000
111.0700 52.0000 1.0000
111.1400 59.0000 1.0000
111.2100 57.0000 1.0000
111.2800 85.0000 1.0000
111.3500 76.0000 1.0000
111.4200 64.0000 1.0000
111.4900 70.0000 1.0000
111.5600 73.0000 1.0000
111.6300 45.0000 1.0000
111.7000 60.0000 1.0000
111.7700 56.0000 1.0000
111.8400 58.0000 1.0000
111.9100 67.0000 1.0000
111.9800 57.0000 1.0000
112.0500 78.0000 1.0000
112.1200 91.0000 1.0000
112.1900 63.0000 1.0000
112.2600 63.0000 1.0000
112.3300 54.0000 1.0000
112.4000 64.0000 1.0000
112.4700 70.0000 1.0000
112.5400 64.0000 1.0000
112.6100 57.0000 1.0000
112.6800 64.0000 1.0000
112.7500 58.0000 1.0000
112.8200 65.0000 1.0000
112.8900 79.0000 1.0000
112.9600 70.0000 1.0000
113.0300 68.0000 1.0000
113.1000 61.0000 1.0000
113.1700 75.0000 1.0000
113.2400 61.0000 1.0000
113.3100 62.0000 1.0000
113.3800 64.0000 1.0000
113.4500 82.0000 1.0000
113.5200 54.0000 1.0000
113.5900 74.0000 1.0000
113.6600 66.0000 1.0000
113.7300 68.0000 1.0000
113.8000 75.0000 1.0000
113.8700 65.0000 1.0000
113.9400 75.0000 1.0000
114.0100 69.0000 1.0000
114.0800 81.0000 1.0000
114.1500 60.0000 1.0000
114.2200 57.0000 1.0000
114.2900 70.0000 1.0000
114.3600 91.0000 1.0000
114.4300 71.0000 1.0000
114.5000 54.0000 1.0000
114.5700 84.0000 1.0000
114.6400 83.0000 1.0000
114.7100 61.0000 1.0000
114.7800 85.0000 1.0000
114.8500 55.0000 1.0000
114.9200 60.0000 1.0000
114.9900 81.0000 1.0000
115.0600 72.0000 1.0000
115.1300 71.0000 1.0000
115.2000 91.0000 1.0000
115.2700 70.0000 1.0000
115.3400 88.0000 1.0000
115.4100 71.0000 1.0000
115.4800 81.0000 1.0000
115.5500 64.0000 1.0000
115.6200 66.0000 1.0000
115.6900 77.0000 1.0000
115.7600 80.0000 1.0000
115.8300 87.0000 1.0000
115.9000 83.0000 1.0000
115.9700 68.0000 1.0000
116.0400 77.0000 1.0000
116.1100 76.0000 1.0000
116.1800 82.0000 1.0000
116.2500 84.0000 1.0000
116.3200 61.0000 1.0000
116.3900 73.0000 1.0000
116.4600 66.0000 1.0000
116.5300 76.0000 1.0000
116.6000 73.0000 1.0000
116.6700 82.0000 1.0000
116.7400 81.0000 1.0000
116.8100 63.0000 1.0000
116.8800 63.0000 1.0000
116.9500 68.0000 1.0000
117.0200 70.0000 1.0000
117.0900 63.0000 1.0000
117.1600 70.0000 1.0000
117.2300 74.0000 1.0000
117.3000 83.0000 1.0000
117.3700 67.0000 1.0000
117.4400 67.0000 1.0000
117.5100 68.0000 1.0000
117.5800 89.0000 1.0000
117.6500 60.0000 1.0000
117.7200 72.0000 1.0000
117.7900 63.0000 1.0000
117.8600 81.0000 1.0000
117.9300 81.0000 1.0000
118.0000 83.0000 1.0000
118.0700 63.0000 1.0000
118.1400 61.0000 1.0000
118.2100 69.0000 1.0000
118.2800 75.0000 1.0000
118.3500 63.0000 1.0000
118.4200 74.0000 1.0000
118.4900 73.0000 1.0000
118.5600 74.0000 1.0000
118.6300 78.0000 1.0000
118.7000 76.0000 1.0000
118.7700 67.0000 1.0000
118.8400 58.0000 1.0000
118.9100 86.0000 1.0000
118.9800 72.0000 1.0000
119.0500 79.0000 1.0000
119.1200 90.0000 1.0000
119.1900 74.0000 1.0000
119.2600 91.0000 1.0000
119.3300 87.0000 1.0000
119.4000 76.0000 1.0000
119.4700 81.0000 1.0000
119.5400 73.0000 1.0000
119.6100 78.0000 1.0000
119.6800 94.0000 1.0000
119.7500 65.0000 1.0000
119.8200 98.0000 1.0000
119.8900 61.0000 1.0000
119.9600 84.0000 1.0000
120.0000 74.0000 1.0000
*RAS_INT_END
*RAS_DATA_END